Workbook

Sheet fecal_neg_0w
A1: FeatureID | B1: Ctrl_n | C1: Vnam_n | D1: U_stat | E1: p-val | F1: q-val_BH | G1: q-val_BKY | H1: Ctrl_mean | I1: Vnam_mean | J1: lfc | K1: Name | L1: ReName | M1: Annotated | N1: Interested
A2: 554.34702-15.063 | B2: 9 | C2: 6 | D2: 28 | E2: 0.95464535 | F2: 0.96454972 | G2: 0.75420585 | H2: 330253.25 | I2: 306677.83 | J2: -0.10684889 | K2: Lysolecithin | L2: LysoPC | M2: o | N2: Glycerophospholipid metabolism
A3: 524.27889-13.665 | B3: 9 | C3: 6 | D3: 10 | E3: 0.04955045 | F3: 0.10171194 | G3: 0.079531142 | H3: 547281.14 | I3: 1888822 | J3: 1.7871328 | K3: lysophosphatidylethanolamine (22:6(4Z,7Z,10Z,13Z,16Z,19Z)/0:0) | L3: LysoPE(22:6(4Z,7Z,10Z,13Z,16Z,19Z)/0:0) | M3: o | N3: Glycerophospholipid metabolism
A4: 204.06668-7.999 | B4: 9 | C4: 6 | D4: 27 | E4: 1 | F4: 1 | G4: 0.78192532 | H4: 2607977.2 | I4: 2694200.9 | J4: 0.046926146 | K4: Indole-3-lactic acid | L4: ILA | M4: o | N4: Interested
A5: 59.01388-1.062 | B5: 9 | C5: 6 | D5: 50 | E5: 0.0079538841 | F5: 0.039401611 | G5: 0.030809117 | H5: 25091727 | I5: 13057110 | J5: -0.94237614 | K5: Acetic acid | L5: Acetate | M5: o | N5: SCFAs
A6: 73.02954-1.169 | B6: 9 | C6: 6 | D6: 33 | E6: 0.52867133 | F6: 0.59201794 | G6: 0.46291382 | H6: 10233183 | I6: 9052587.9 | J6: -0.17685277 | K6: Propionic acid | M6: o
A7: 73.02956-1.68 | B7: 9 | C7: 6 | D7: 23 | E7: 0.68891109 | F7: 0.73873474 | G7: 0.5776354 | H7: 22436768 | I7: 30952900 | J7: 0.4642097 | K7: Propionic acid | L7: Propionate | M7: o | N7: SCFAs
A8: 173.00928-7.727 | B8: 9 | C8: 6 | D8: 38 | E8: 0.22377622 | F8: 0.28851546 | G8: 0.22559754 | H8: 1295059.9 | I8: 872379.82 | J8: -0.56999047 | K8: (Z)-Aconitic Acid | M8: o
A9: 266.0897-1.761 | B9: 9 | C9: 6 | D9: 48 | E9: 0.011988012 | F9: 0.046954873 | G9: 0.036715204 | H9: 3875154.7 | I9: 607502.13 | J9: -2.6732925 | K9: Adenosine | M9: o | N9: Interested
A10: 99.00882-1.554 | B10: 9 | C10: 6 | D10: 27 | E10: 1 | F10: 1 | G10: 0.78192532 | H10: 5355260.7 | I10: 6690969.6 | J10: 0.32125848 | K10: 2-Oxoglutaric acid | M10: o
A11: 74.02478-1.04 | B11: 9 | C11: 6 | D11: 52 | E11: 0.0015984016 | F11: 0.030772822 | G11: 0.024062048 | H11: 4293480.6 | I11: 1404188.8 | J11: -1.6124108 | K11: Glycine | M11: o | N11: Interested
A12: 191.01995-1.447 | B12: 9 | C12: 6 | D12: 8 | E12: 0.025574426 | F12: 0.069139693 | G12: 0.054062077 | H12: 3155549.3 | I12: 12684107 | J12: 2.0070589 | K12: Citric acid | M12: o
A13: 133.01433-1.134 | B13: 9 | C13: 6 | D13: 33.5 | E13: 0.47910737 | F13: 0.54694954 | G13: 0.42767369 | H13: 12548715 | I13: 10138912 | J13: -0.30763679 | K13: L-(-)-Malic acid | L13: Malte | M13: o | N13: TCA cycle
A14: 117.01941-1.181 | B14: 9 | C14: 6 | D14: 19 | E14: 0.38841159 | F14: 0.4554854 | G14: 0.35615557 | H14: 18370955 | I14: 25062783 | J14: 0.44812 | K14: Succinic acid | M14: o
A15: 117.01943-1.682 | B15: 9 | C15: 6 | D15: 20 | E15: 0.45594406 | F15: 0.52099207 | G15: 0.4073769 | H15: 80509199 | I15: 1.249208e+08 | J15: 0.63378821 | K15: Succinic acid | L15: Succinate | M15: o | N15: TCA cycle
A16: 173.00927-1.126 | B16: 9 | C16: 6 | D16: 10 | E16: 0.04955045 | F16: 0.10171194 | G16: 0.079531142 | H16: 652628.35 | I16: 3779921.9 | J16: 2.5340229 | K16: trans-Aconitic acid | L16: Aconitate | M16: o | N16: TCA cycle
A17: 173.00929-1.445 | B17: 9 | C17: 6 | D17: 10 | E17: 0.04955045 | F17: 0.10171194 | G17: 0.079531142 | H17: 359501.08 | I17: 2553922 | J17: 2.8286465 | K17: trans-Aconitic acid | M17: o
A18: 162.05616-5.885 | B18: 9 | C18: 6 | D18: 36 | E18: 0.32767233 | F18: 0.39351904 | G18: 0.3077025 | H18: 30235.314 | I18: 33372.8 | J18: 0.14243818 | K18: 3-hydroxy-3-methyloxindole | L18: HMOI | M18: o | N18: Tryptophan metabolism
A19: 223.07258-6.267 | B19: 9 | C19: 6 | D19: 20 | E19: 0.45594406 | F19: 0.52099207 | G19: 0.4073769 | H19: 1039594.6 | I19: 2226462.5 | J19: 1.0987322 | K19: 3-hydroxy-D-kynurenine | L19: 3-HK | M19: o | N19: Tryptophan metabolism
A20: 145.01435-1.439 | B20: 9 | C20: 6 | D20: 47 | E20: 0.017582418 | F20: 0.057054645 | G20: 0.044612472 | H20: 16844963 | I20: 2566223.1 | J20: -2.7145987 | K20: 2-Oxoglutaric acid | L20: α-KG | M20: o | N20: TCA cycle
A21: 206.04578-6.434 | B21: 9 | C21: 6 | D21: 43 | E21: 0.066333666 | F21: 0.12328769 | G21: 0.096401763 | H21: 3.3896185e+08 | I21: 1.6309709e+08 | J21: -1.0553919 | K21: 4-(2-Aminophenyl)-2,4-dioxobutanoic acid | L21: 4-(2-Aminophenyl)-2,4-dioxobutanoate | M21: o | N21: Tryptophan metabolism
A22: 219.07772-2.061 | B22: 9 | C22: 6 | D22: 10 | E22: 0.04955045 | F22: 0.10171194 | G22: 0.079531142 | H22: 235484.72 | I22: 2530351.3 | J22: 3.4256324 | K22: 5-Hydroxy-DL-tryptophan | L22: 5-HTP | M22: o | N22: Tryptophan metabolism
A23: 191.0199-1.113 | B23: 9 | C23: 6 | D23: 6 | E23: 0.011988012 | F23: 0.046954873 | G23: 0.036715204 | H23: 1672309.5 | I23: 15590857 | J23: 3.2207864 | K23: Citric acid | L23: Citrate | M23: o | N23: TCA cycle
A24: 190.05117-7.239 | B24: 9 | C24: 6 | D24: 47 | E24: 0.017582418 | F24: 0.057054645 | G24: 0.044612472 | H24: 23251808 | I24: 9032406.7 | J24: -1.3641605 | K24: 5-Hydroxyindole-3-acetic acid | L24: 5-HIAA | M24: o | N24: Tryptophan metabolism
A25: 220.06169-7.766 | B25: 9 | C25: 6 | D25: 32 | E25: 0.60699301 | F25: 0.66393492 | G25: 0.51914752 | H25: 1133304.7 | I25: 1090218.5 | J25: -0.055918412 | K25: Indole-3-acetic acid | L25: IAA | M25: o | N25: Tryptophan metabolism
A26: 202.05128-16.408 | B26: 9 | C26: 6 | D26: 20 | E26: 0.45594406 | F26: 0.52099207 | G26: 0.4073769 | H26: 5403362.5 | I26: 6303913.7 | J26: 0.22239032 | K26: INDOLE-3-PYRUVATE | L26: IPA | M26: o | N26: Tryptophan metabolism
A27: 202.05126-17.793 | B27: 9 | C27: 6 | D27: 46 | E27: 0.025574426 | F27: 0.069139693 | G27: 0.054062077 | H27: 5209058.5 | I27: 2600985.6 | J27: -1.0019642 | K27: Indole-3-pyruvic acid | M27: o
A28: 202.05124-16.927 | B28: 9 | C28: 6 | D28: 45 | E28: 0.035964036 | F28: 0.082058517 | G28: 0.064163632 | H28: 4675936.4 | I28: 3006583.3 | J28: -0.63713038 | K28: Indole-3-pyruvic acid | M28: o
A29: 293.11461-6.013 | B29: 9 | C29: 6 | D29: 51 | E29: 0.0027972028 | F29: 0.030772822 | G29: 0.024062048 | H29: 2639970.9 | I29: 188683.32 | J29: -3.8064832 | K29: 6-Hydroxymelatonin | L29: 6-OHM | M29: o | N29: Tryptophan metabolism
A30: 188.03554-5.821 | B30: 9 | C30: 6 | D30: 50 | E30: 0.0047952048 | F30: 0.034120286 | G30: 0.026679515 | H30: 16091364 | I30: 3840133.4 | J30: -2.0670583 | K30: Kynurenic acid | L30: KYNA | M30: o | N30: Tryptophan metabolism
A31: 235.109-5.862 | B31: 9 | C31: 6 | D31: 50 | E31: 0.0047952048 | F31: 0.034120286 | G31: 0.026679515 | H31: 3186318.2 | I31: 292000.76 | J31: -3.4478463 | K31: N1-Acetyl-5-methoxykynuramine | L31: AMK | M31: o | N31: Tryptophan metabolism
A32: 188.03553-5.887 | B32: 9 | C32: 6 | D32: 51 | E32: 0.0027972028 | F32: 0.030772822 | G32: 0.024062048 | H32: 17900480 | I32: 3838390.1 | J32: -2.221425 | K32: 4-(2-Aminophenyl)-2,4-dioxobutanoic acid | M32: o
A33: 492.24311-9.626 | B33: 9 | C33: 6 | D33: 8 | E33: 0.025574426 | F33: 0.069139693 | G33: 0.054062077 | H33: 81455.173 | I33: 5803124.4 | J33: 6.1546797 | K33: (−)-Epothilone A | M33: o
A34: 492.24317-8.208 | B34: 9 | C34: 6 | D34: 14.5 | E34: 0.14412703 | F34: 0.21047475 | G34: 0.16457554 | H34: 1197011 | I34: 9269258 | J34: 2.9530175 | K34: (−)-Epothilone A | M34: o
A35: 385.14415-8.335 | B35: 9 | C35: 6 | D35: 54 | E35: 0.0003996004 | F35: 0.030772822 | G35: 0.024062048 | H35: 6770738 | I35: 700937.02 | J35: -3.2719563 | M35: x
A36: 506.25876-12.541 | B36: 9 | C36: 6 | D36: 9 | E36: 0.035964036 | F36: 0.082058517 | G36: 0.064163632 | H36: 578750.22 | I36: 4669448.5 | J36: 3.0122394 | K36: (−)-Epothilone B | M36: o
A37: 327.08771-8.088 | B37: 9 | C37: 6 | D37: 54 | E37: 0.0003996004 | F37: 0.030772822 | G37: 0.024062048 | H37: 6348547.5 | I37: 107333.39 | J37: -5.8862557 | M37: x
A38: 255.06648-9.02 | B38: 9 | C38: 6 | D38: 45 | E38: 0.035964036 | F38: 0.082058517 | G38: 0.064163632 | H38: 2499579.4 | I38: 1319632.1 | J38: -0.92154952 | K38: (−)-pinocembrin | M38: o
A39: 441.24185-10.175 | B39: 9 | C39: 6 | D39: 54 | E39: 0.0003996004 | F39: 0.030772822 | G39: 0.024062048 | H39: 3862351.9 | I39: 459169.8 | J39: -3.0723799 | M39: x
A40: 255.06643-11.598 | B40: 9 | C40: 6 | D40: 28 | E40: 0.95464535 | F40: 0.96454972 | G40: 0.75420585 | H40: 2814237.2 | I40: 2452228.2 | J40: -0.19865069 | K40: (−)-pinocembrin | M40: o
...

Sheet fecal_neg_1w
A1: FeatureID | B1: Ctrl_n | C1: Vnam_n | D1: U_stat | E1: p-val | F1: q-val_BH | G1: q-val_BKY | H1: Ctrl_mean | I1: Vnam_mean | J1: lfc | K1: Name | L1: ReName | M1: Annotated | N1: Interested | O1: 0w_q-val_BKY
A2: 554.34702-15.063 | B2: 11 | C2: 10 | D2: 29 | E2: 0.072549257 | F2: 0.095893041 | G2: 0.031866615 | H2: 309668.37 | I2: 419442.71 | J2: 0.43774975 | K2: Lysolecithin | L2: LysoPC | M2: o | N2: Glycerophospholipid metabolism | O2: =VLOOKUP(A2,fecal_neg_0w!A:G,7,FALSE) -> 0.75420585
A3: 524.27889-13.665 | B3: 11 | C3: 10 | D3: 3 | E3: 0.00028726572 | F3: 0.0049017378 | G3: 0.0016289169 | H3: 598214.84 | I3: 2800992.9 | J3: 2.2272027 | K3: lysophosphatidylethanolamine (22:6(4Z,7Z,10Z,13Z,16Z,19Z)/0:0) | L3: LysoPE(22:6(4Z,7Z,10Z,13Z,16Z,19Z)/0:0) | M3: o | N3: Glycerophospholipid metabolism | O3: =VLOOKUP(A3,fecal_neg_0w!A:G,7,FALSE) -> 0.079531142
A4: 204.06668-7.999 | B4: 11 | C4: 10 | D4: 84 | E4: 0.044066532 | F4: 0.062855194 | G4: 0.020887671 | H4: 3086450.2 | I4: 2072191.5 | J4: -0.57479119 | K4: Indole-3-lactic acid | L4: ILA | M4: o | N4: Interested | O4: =VLOOKUP(A4,fecal_neg_0w!A:G,7,FALSE) -> 0.78192532
A5: 266.0897-1.761 | B5: 11 | C5: 10 | D5: 106 | E5: 0.00037639672 | F5: 0.0049017378 | G5: 0.0016289169 | H5: 9145147.2 | I5: 446405.98 | J5: -4.3565782 | K5: Adenosine | M5: o | N5: Interested | O5: =VLOOKUP(A5,fecal_neg_0w!A:G,7,FALSE) -> 0.036715204
A6: 74.02478-1.04 | B6: 11 | C6: 10 | D6: 106 | E6: 0.00037639672 | F6: 0.0049017378 | G6: 0.0016289169 | H6: 7592849.4 | I6: 1389366 | J6: -2.4502147 | K6: Glycine | M6: o | N6: Interested | O6: =VLOOKUP(A6,fecal_neg_0w!A:G,7,FALSE) -> 0.024062048
A7: 73.02956-1.68 | B7: 11 | C7: 10 | D7: 83 | E7: 0.05273059 | F7: 0.072610328 | G7: 0.02412944 | H7: 38461491 | I7: 21287480 | J7: -0.85340948 | K7: Propionic acid | L7: Propionate | M7: o | N7: SCFAs | O7: =VLOOKUP(A7,fecal_neg_0w!A:G,7,FALSE) -> 0.5776354
A8: 173.00928-7.727 | B8: 11 | C8: 10 | D8: 71 | E8: 0.27506299 | F8: 0.31881709 | G8: 0.10594743 | H8: 1193510.6 | I8: 931045.77 | J8: -0.35828737 | K8: (Z)-Aconitic Acid | M8: o | O8: =VLOOKUP(A8,fecal_neg_0w!A:G,7,FALSE) -> 0.22559754
A9: 148.04389-1.437 | B9: 11 | C9: 10 | D9: 101 | E9: 0.0013552612 | F9: 0.0065169661 | G9: 0.0021656801 | H9: 1601124.9 | I9: 407135.08 | J9: -1.9755064 | K9: L-(−)-methionine | L9: Methionine | M9: o | N9: Interested | O9: =VLOOKUP(A9,fecal_neg_0w!A:G,7,FALSE) -> 0.054062077
A10: 99.00882-1.554 | B10: 11 | C10: 10 | D10: 82 | E10: 0.062031042 | F10: 0.08377368 | G10: 0.02783918 | H10: 8070345.4 | I10: 5639099.8 | J10: -0.51716555 | K10: 2-Oxoglutaric acid | M10: o | O10: =VLOOKUP(A10,fecal_neg_0w!A:G,7,FALSE) -> 0.78192532
A11: 104.03535-1.028 | B11: 11 | C11: 10 | D11: 106 | E11: 0.00037639672 | F11: 0.0049017378 | G11: 0.0016289169 | H11: 15703040 | I11: 2193395.2 | J11: -2.8398063 | K11: L-Serine | M11: o | N11: Interested | O11: =VLOOKUP(A11,fecal_neg_0w!A:G,7,FALSE) -> 0.079531142
A12: 191.01995-1.447 | B12: 11 | C12: 10 | D12: 40 | E12: 0.30722637 | F12: 0.35219034 | G12: 0.11703783 | H12: 6562811.7 | I12: 9823791.2 | J12: 0.58196586 | K12: Citric acid | M12: o | O12: =VLOOKUP(A12,fecal_neg_0w!A:G,7,FALSE) -> 0.054062077
A13: 133.01433-1.134 | B13: 11 | C13: 10 | D13: 59 | E13: 0.80532417 | F13: 0.83022411 | G13: 0.27589522 | H13: 16690076 | I13: 15354864 | J13: -0.12029477 | K13: L-(-)-Malic acid | L13: Malate | M13: o | N13: TCA cycle | O13: =VLOOKUP(A13,fecal_neg_0w!A:G,7,FALSE) -> 0.42767369
A14: 302.13598-1.085 | B14: 11 | C14: 10 | D14: 15 | E14: 0.0054107294 | F14: 0.012558109 | G14: 0.0041732375 | H14: 1035859.2 | I14: 4274765.8 | J14: 2.0450175 | K14: nicotianamine | M14: o | N14: Interested | O14: =VLOOKUP(A14,fecal_neg_0w!A:G,7,FALSE) -> 0.079531142
A15: 117.01943-1.682 | B15: 11 | C15: 10 | D15: 84 | E15: 0.044689913 | F15: 0.062855194 | G15: 0.020887671 | H15: 1.5454625e+08 | I15: 81560117 | J15: -0.92210289 | K15: Succinic acid | L15: Succinate | M15: o | N15: TCA cycle | O15: =VLOOKUP(A15,fecal_neg_0w!A:G,7,FALSE) -> 0.4073769
A16: 59.01388-1.062 | B16: 11 | C16: 10 | D16: 100 | E16: 0.0016675829 | F16: 0.0070060764 | G16: 0.0023282184 | H16: 27357145 | I16: 12511520 | J16: -1.1286606 | K16: Acetic acid | L16: Acetate | M16: o | N16: SCFAs | O16: =VLOOKUP(A16,fecal_neg_0w!A:G,7,FALSE) -> 0.030809117
A17: 145.01435-1.439 | B17: 11 | C17: 10 | D17: 103 | E17: 0.00082327304 | F17: 0.005616741 | G17: 0.0018665225 | H17: 11467943 | I17: 2150873.9 | J17: -2.4146118 | K17: 2-Oxoglutaric acid | L17: α-KG | M17: o | N17: TCA cycle | O17: =VLOOKUP(A17,fecal_neg_0w!A:G,7,FALSE) -> 0.044612472
A18: 162.05616-5.885 | B18: 11 | C18: 10 | D18: 67 | E18: 0.41805191 | F18: 0.46632216 | G18: 0.15496545 | H18: 30795.006 | I18: 29449.811 | J18: -0.064438038 | K18: 3-hydroxy-3-methyloxindole | L18: HMOI | M18: o | N18: Tryptophan metabolism | O18: =VLOOKUP(A18,fecal_neg_0w!A:G,7,FALSE) -> 0.3077025
A19: 191.0199-1.113 | B19: 11 | C19: 10 | D19: 15 | E19: 0.0054107294 | F19: 0.012558109 | G19: 0.0041732375 | H19: 2809045.9 | I19: 12963869 | J19: 2.2063442 | K19: Citric acid | L19: Citrate | M19: o | N19: TCA cycle | O19: =VLOOKUP(A19,fecal_neg_0w!A:G,7,FALSE) -> 0.036715204
A20: 173.00927-1.126 | B20: 11 | C20: 10 | D20: 6 | E20: 0.00063719487 | F20: 0.0053114036 | G20: 0.0017650546 | H20: 974694.21 | I20: 4360562.9 | J20: 2.1614928 | K20: trans-Aconitic acid | L20: Aconitate | M20: o | N20: TCA cycle | O20: =VLOOKUP(A20,fecal_neg_0w!A:G,7,FALSE) -> 0.079531142
A21: 206.04578-6.434 | B21: 11 | C21: 10 | D21: 77 | E21: 0.1300298 | F21: 0.16213989 | G21: 0.053881381 | H21: 5.0060448e+08 | I21: 3.2058251e+08 | J21: -0.64297547 | K21: 4-(2-Aminophenyl)-2,4-dioxobutanoic acid | L21: 4-(2-Aminophenyl)-2,4-dioxobutanoate | M21: o | N21: Tryptophan metabolism | O21: =VLOOKUP(A21,fecal_neg_0w!A:G,7,FALSE) -> 0.096401763
A22: 223.07258-6.267 | B22: 11 | C22: 10 | D22: 88 | E22: 0.022103705 | F22: 0.034053694 | G22: 0.011316525 | H22: 979077.99 | I22: 398762.03 | J22: -1.2958957 | K22: 3-hydroxy-D-kynurenine | L22: 3-HK | M22: o | N22: Tryptophan metabolism | O22: =VLOOKUP(A22,fecal_neg_0w!A:G,7,FALSE) -> 0.4073769
A23: 219.07772-2.061 | B23: 11 | C23: 10 | D23: 19 | E23: 0.012425127 | F23: 0.021750952 | G23: 0.0072281492 | H23: 390500.49 | I23: 3435681.7 | J23: 3.1372001 | K23: 5-Hydroxy-DL-tryptophan | L23: 5-HTP | M23: o | N23: Tryptophan metabolism | O23: =VLOOKUP(A23,fecal_neg_0w!A:G,7,FALSE) -> 0.079531142
A24: 190.05117-7.239 | B24: 11 | C24: 10 | D24: 98 | E24: 0.0027646719 | F24: 0.008709733 | G24: 0.0028943676 | H24: 40820960 | I24: 12615712 | J24: -1.6940885 | K24: 5-Hydroxyindole-3-acetic acid | L24: 5-HIAA | M24: o | N24: Tryptophan metabolism | O24: =VLOOKUP(A24,fecal_neg_0w!A:G,7,FALSE) -> 0.044612472
A25: 220.06169-7.766 | B25: 11 | C25: 10 | D25: 62 | E25: 0.64715634 | F25: 0.68598252 | G25: 0.2279617 | H25: 1160616.8 | I25: 1050547.1 | J25: -0.14375088 | K25: Indole-3-acetic acid | L25: IAA | M25: o | N25: Tryptophan metabolism | O25: =VLOOKUP(A25,fecal_neg_0w!A:G,7,FALSE) -> 0.51914752
A26: 202.05128-16.408 | B26: 11 | C26: 10 | D26: 59 | E26: 0.80532417 | F26: 0.83022411 | G26: 0.27589522 | H26: 5848637.3 | I26: 5816277.4 | J26: -0.0080044485 | K26: INDOLE-3-PYRUVATE | L26: IPA | M26: o | N26: Tryptophan metabolism | O26: =VLOOKUP(A26,fecal_neg_0w!A:G,7,FALSE) -> 0.4073769
A27: 202.05124-16.927 | B27: 11 | C27: 10 | D27: 95 | E27: 0.0053506989 | F27: 0.012558109 | G27: 0.0041732375 | H27: 4781223.1 | I27: 2479253.6 | J27: -0.94747384 | K27: Indole-3-pyruvic acid | M27: o | O27: =VLOOKUP(A27,fecal_neg_0w!A:G,7,FALSE) -> 0.064163632
A28: 202.05126-17.793 | B28: 11 | C28: 10 | D28: 88 | E28: 0.022103705 | F28: 0.034053694 | G28: 0.011316525 | H28: 5134932.4 | I28: 3143133.2 | J28: -0.70814186 | K28: Indole-3-pyruvic acid | M28: o | O28: =VLOOKUP(A28,fecal_neg_0w!A:G,7,FALSE) -> 0.054062077
A29: 293.11461-6.013 | B29: 11 | C29: 10 | D29: 101 | E29: 0.0013552612 | F29: 0.0065169661 | G29: 0.0021656801 | H29: 1543547.9 | I29: 207993.66 | J29: -2.8916388 | K29: 6-Hydroxymelatonin | L29: 6-OHM | M29: o | N29: Tryptophan metabolism | O29: =VLOOKUP(A29,fecal_neg_0w!A:G,7,FALSE) -> 0.024062048
A30: 188.03554-5.821 | B30: 11 | C30: 10 | D30: 110 | E30: 0.00012415446 | F30: 0.0049017378 | G30: 0.0016289169 | H30: 19229459 | I30: 1233753.5 | J30: -3.9621921 | K30: Kynurenic acid | L30: KYNA | M30: o | N30: Tryptophan metabolism | O30: =VLOOKUP(A30,fecal_neg_0w!A:G,7,FALSE) -> 0.026679515
A31: 235.109-5.862 | B31: 11 | C31: 10 | D31: 99 | E31: 0.0021899994 | F31: 0.0078126999 | G31: 0.0025962708 | H31: 1208889.8 | I31: 257764.84 | J31: -2.2295553 | K31: N1-Acetyl-5-methoxykynuramine | L31: AMK | M31: o | N31: Tryptophan metabolism | O31: =VLOOKUP(A31,fecal_neg_0w!A:G,7,FALSE) -> 0.026679515
A32: 276.82461-0.888 | B32: 11 | C32: 10 | D32: 0 | E32: 3.3941334e-05 | F32: 0.0049017378 | G32: 0.0016289169 | H32: 40812.735 | I32: 1270684.5 | J32: 4.9604427 | M32: x | O32: =VLOOKUP(A32,fecal_neg_0w!A:G,7,FALSE) -> 0.024062048
A33: 73.02954-1.169 | B33: 11 | C33: 10 | D33: 99 | E33: 0.0021899994 | F33: 0.0078126999 | G33: 0.0025962708 | H33: 17964622 | I33: 8726273 | J33: -1.041721 | K33: Propionic acid | M33: o | O33: =VLOOKUP(A33,fecal_neg_0w!A:G,7,FALSE) -> 0.46291382
A34: 294.8854-0.91 | B34: 11 | C34: 10 | D34: 0 | E34: 4.8754519e-05 | F34: 0.0049017378 | G34: 0.0016289169 | H34: 34116.267 | I34: 3806854.7 | J34: 6.8019959 | M34: x | O34: =VLOOKUP(A34,fecal_neg_0w!A:G,7,FALSE) -> 0.024062048
A35: 293.88335-0.922 | B35: 11 | C35: 10 | D35: 0 | E35: 4.8754519e-05 | F35: 0.0049017378 | G35: 0.0016289169 | H35: 29062.646 | I35: 1981949.8 | J35: 6.0916106 | M35: x | O35: =VLOOKUP(A35,fecal_neg_0w!A:G,7,FALSE) -> 0.024062048
A36: 609.36509-11.806 | B36: 11 | C36: 10 | D36: 1 | E36: 8.7339716e-05 | F36: 0.0049017378 | G36: 0.0016289169 | H36: 39744.138 | I36: 1496263.5 | J36: 5.2344784 | M36: x | O36: =VLOOKUP(A36,fecal_neg_0w!A:G,7,FALSE) -> 0.096401763
A37: 281.11206-5.123 | B37: 11 | C37: 10 | D37: 110 | E37: 9.2481722e-05 | F37: 0.0049017378 | G37: 0.0016289169 | H37: 454786.13 | I37: 55394.138 | J37: -3.037383 | M37: x | O37: =VLOOKUP(A37,fecal_neg_0w!A:G,7,FALSE) -> 0.13919232
A38: 625.36007-11.866 | B38: 11 | C38: 10 | D38: 1 | E38: 0.00010684099 | F38: 0.0049017378 | G38: 0.0016289169 | H38: 46800.903 | I38: 2387645.6 | J38: 5.6729085 | M38: x | O38: =VLOOKUP(A38,fecal_neg_0w!A:G,7,FALSE) -> 0.030212282
A39: 430.86038-0.938 | B39: 11 | C39: 10 | D39: 0 | E39: 0.00011203034 | F39: 0.0049017378 | G39: 0.0016289169 | H39: 15731.473 | I39: 487877.76 | J39: 4.954794 | M39: x | O39: =VLOOKUP(A39,fecal_neg_0w!A:G,7,FALSE) -> 0.048728208
A40: 429.85915-0.939 | B40: 11 | C40: 10 | D40: 0 | E40: 0.00011203034 | F40: 0.0049017378 | G40: 0.0016289169 | H40: 13541.183 | I40: 468143.56 | J40: 5.1115254 | M40: x | O40: =VLOOKUP(A40,fecal_neg_0w!A:G,7,FALSE) -> 0.048728208
...

Sheet fecal_neg_2w
A1: FeatureID | B1: Ctrl_n | C1: Vnam_n | D1: U_stat | E1: p-val | F1: q-val_BH | G1: q-val_BKY | H1: Ctrl_mean | I1: Vnam_mean | J1: lfc | K1: Name | L1: ReName | M1: Annotated | N1: Interested | O1: 0w_q-val_BKY
A2: 554.34702-15.063 | B2: 11 | C2: 10 | D2: 51 | E2: 0.80532417 | F2: 0.82496388 | G2: 0.22279512 | H2: 301116.13 | I2: 367642.4 | J2: 0.28798316 | K2: Lysolecithin | L2: LysoPC | M2: o | N2: Glycerophospholipid metabolism | O2: =VLOOKUP(A2,fecal_neg_0w!A:G,7,FALSE) -> 0.75420585
A3: 524.27889-13.665 | B3: 11 | C3: 10 | D3: 2 | E3: 0.00021821505 | F3: 0.0019641647 | G3: 0.00053045512 | H3: 621424.04 | I3: 2707711.5 | J3: 2.1234241 | K3: lysophosphatidylethanolamine (22:6(4Z,7Z,10Z,13Z,16Z,19Z)/0:0) | L3: LysoPE(22:6(4Z,7Z,10Z,13Z,16Z,19Z)/0:0) | M3: o | N3: Glycerophospholipid metabolism | O3: =VLOOKUP(A3,fecal_neg_0w!A:G,7,FALSE) -> 0.079531142
A4: 204.06668-7.999 | B4: 11 | C4: 10 | D4: 83 | E4: 0.050126888 | F4: 0.065428378 | G4: 0.017670014 | H4: 2552634 | I4: 1758843.8 | J4: -0.53735927 | K4: Indole-3-lactic acid | L4: ILA | M4: o | N4: Interested | O4: =VLOOKUP(A4,fecal_neg_0w!A:G,7,FALSE) -> 0.78192532
A5: 59.01388-1.062 | B5: 11 | C5: 10 | D5: 89 | E5: 0.018324308 | F5: 0.026005464 | G5: 0.0070232052 | H5: 25101901 | I5: 16261151 | J5: -0.62636724 | K5: Acetic acid | L5: Acetate | M5: o | N5: SCFAs | O5: =VLOOKUP(A5,fecal_neg_0w!A:G,7,FALSE) -> 0.030809117
A6: 73.02954-1.169 | B6: 11 | C6: 10 | D6: 94 | E6: 0.0067062756 | F6: 0.010801894 | G6: 0.0029172299 | H6: 16016567 | I6: 10095583 | J6: -0.66584066 | K6: Propionic acid | M6: o | O6: =VLOOKUP(A6,fecal_neg_0w!A:G,7,FALSE) -> 0.46291382
A7: 73.02956-1.68 | B7: 11 | C7: 10 | D7: 69 | E7: 0.34178646 | F7: 0.37688434 | G7: 0.10178384 | H7: 40880832 | I7: 31438229 | J7: -0.37890459 | K7: Propionic acid | L7: Propionate | M7: o | N7: SCFAs | O7: =VLOOKUP(A7,fecal_neg_0w!A:G,7,FALSE) -> 0.5776354
A8: 173.00928-7.727 | B8: 11 | C8: 10 | D8: 71 | E8: 0.27506299 | F8: 0.30855017 | G8: 0.083329071 | H8: 1239481.9 | I8: 813265.16 | J8: -0.60793952 | K8: (Z)-Aconitic Acid | M8: o | O8: =VLOOKUP(A8,fecal_neg_0w!A:G,7,FALSE) -> 0.22559754
A9: 266.0897-1.761 | B9: 11 | C9: 10 | D9: 106 | E9: 0.00037639672 | F9: 0.002033634 | G9: 0.00054921644 | H9: 5921701.1 | I9: 340657.34 | J9: -4.1196185 | K9: Adenosine | M9: o | N9: Interested | O9: =VLOOKUP(A9,fecal_neg_0w!A:G,7,FALSE) -> 0.036715204
A10: 99.00882-1.554 | B10: 11 | C10: 10 | D10: 47 | E10: 0.59740627 | F10: 0.62881394 | G10: 0.16982159 | H10: 7441819 | I10: 8109974.9 | J10: 0.12404214 | K10: 2-Oxoglutaric acid | M10: o | O10: =VLOOKUP(A10,fecal_neg_0w!A:G,7,FALSE) -> 0.78192532
A11: 74.02478-1.04 | B11: 11 | C11: 10 | D11: 103 | E11: 0.00082327304 | F11: 0.0025917071 | G11: 0.00069993331 | H11: 5794704.2 | I11: 1390729.3 | J11: -2.0588934 | K11: Glycine | M11: o | N11: Interested | O11: =VLOOKUP(A11,fecal_neg_0w!A:G,7,FALSE) -> 0.024062048
A12: 148.04389-1.437 | B12: 11 | C12: 10 | D12: 102 | E12: 0.0010587485 | F12: 0.0028475882 | G12: 0.00076903824 | H12: 1596740.3 | I12: 351123.06 | J12: -2.1850811 | K12: L-(−)-methionine | L12: Methionine | M12: o | N12: Interested | O12: =VLOOKUP(A12,fecal_neg_0w!A:G,7,FALSE) -> 0.054062077
A13: 133.01433-1.134 | B13: 11 | C13: 10 | D13: 71 | E13: 0.27506299 | F13: 0.30855017 | G13: 0.083329071 | H13: 20121328 | I13: 14874848 | J13: -0.43585054 | K13: L-(-)-Malic acid | L13: Malic acid | M13: o | N13: TCA cycle | O13: =VLOOKUP(A13,fecal_neg_0w!A:G,7,FALSE) -> 0.42767369
A14: 117.01941-1.181 | B14: 11 | C14: 10 | D14: 83 | E14: 0.052807511 | F14: 0.067974698 | G14: 0.01835769 | H14: 43990746 | I14: 27008876 | J14: -0.70376644 | K14: Succinic acid | M14: o | O14: =VLOOKUP(A14,fecal_neg_0w!A:G,7,FALSE) -> 0.35615557
A15: 117.01943-1.682 | B15: 11 | C15: 10 | D15: 70 | E15: 0.30706927 | F15: 0.34181028 | G15: 0.092311512 | H15: 1.6664831e+08 | I15: 1.1966547e+08 | J15: -0.47779975 | K15: Succinic acid | L15: Succinate | M15: o | N15: TCA cycle | O15: =VLOOKUP(A15,fecal_neg_0w!A:G,7,FALSE) -> 0.4073769
A16: 104.03535-1.028 | B16: 11 | C16: 10 | D16: 103 | E16: 0.00082327304 | F16: 0.0025917071 | G16: 0.00069993331 | H16: 11987566 | I16: 2098445.6 | J16: -2.5141458 | K16: L-Serine | M16: o | N16: Interested | O16: =VLOOKUP(A16,fecal_neg_0w!A:G,7,FALSE) -> 0.079531142
A17: 302.13598-1.085 | B17: 11 | C17: 10 | D17: 6 | E17: 0.00063719487 | F17: 0.0023719039 | G17: 0.00064057184 | H17: 940006.97 | I17: 4572580.2 | J17: 2.2822651 | K17: nicotianamine | M17: o | N17: Interested | O17: =VLOOKUP(A17,fecal_neg_0w!A:G,7,FALSE) -> 0.079531142
A18: 162.05616-5.885 | B18: 11 | C18: 10 | D18: 49 | E18: 0.69853536 | F18: 0.72572132 | G18: 0.19599303 | H18: 30975.152 | I18: 28921.55 | J18: -0.098966509 | K18: 3-hydroxy-3-methyloxindole | L18: HMOI | M18: o | N18: Tryptophan metabolism | O18: =VLOOKUP(A18,fecal_neg_0w!A:G,7,FALSE) -> 0.3077025
A19: 223.07258-6.267 | B19: 11 | C19: 10 | D19: 73 | E19: 0.21783223 | F19: 0.24891377 | G19: 0.067223276 | H19: 885292.62 | I19: 1800036.5 | J19: 1.0237998 | K19: 3-hydroxy-D-kynurenine | L19: 3-HK | M19: o | N19: Tryptophan metabolism | O19: =VLOOKUP(A19,fecal_neg_0w!A:G,7,FALSE) -> 0.4073769
A20: 145.01435-1.439 | B20: 11 | C20: 10 | D20: 104 | E20: 0.00063719487 | F20: 0.0023719039 | G20: 0.00064057184 | H20: 8984519.5 | I20: 1319664.6 | J20: -2.7672701 | K20: 2-Oxoglutaric acid | L20: α-KG | M20: o | N20: TCA cycle | O20: =VLOOKUP(A20,fecal_neg_0w!A:G,7,FALSE) -> 0.044612472
A21: 191.0199-1.113 | B21: 11 | C21: 10 | D21: 8 | E21: 0.0010587485 | F21: 0.0028475882 | G21: 0.00076903824 | H21: 2055456.2 | I21: 16847499 | J21: 3.0350039 | K21: Citric acid | L21: Citrate | M21: o | N21: TCA cycle | O21: =VLOOKUP(A21,fecal_neg_0w!A:G,7,FALSE) -> 0.036715204
A22: 173.00927-1.126 | B22: 11 | C22: 10 | D22: 0 | E22: 0.00012415446 | F22: 0.0019641647 | G22: 0.00053045512 | H22: 672543.13 | I22: 6075640.3 | J22: 3.1753378 | K22: trans-Aconitic acid | L22: Aconitic acid | M22: o | N22: TCA cycle | O22: =VLOOKUP(A22,fecal_neg_0w!A:G,7,FALSE) -> 0.079531142
A23: 206.04578-6.434 | B23: 11 | C23: 10 | D23: 101 | E23: 0.0013552612 | F23: 0.0032063041 | G23: 0.00086591539 | H23: 5.475327e+08 | I23: 1.651758e+08 | J23: -1.7289428 | K23: 4-(2-Aminophenyl)-2,4-dioxobutanoic acid | L23: 4-(2-Aminophenyl)-2,4-dioxobutanoate | M23: o | N23: Tryptophan metabolism | O23: =VLOOKUP(A23,fecal_neg_0w!A:G,7,FALSE) -> 0.096401763
A24: 219.07772-2.061 | B24: 11 | C24: 10 | D24: 8 | E24: 0.0010587485 | F24: 0.0028475882 | G24: 0.00076903824 | H24: 227372.05 | I24: 3823202.8 | J24: 4.0716549 | K24: 5-Hydroxy-DL-tryptophan | L24: 5-HTP | M24: o | N24: Tryptophan metabolism | O24: =VLOOKUP(A24,fecal_neg_0w!A:G,7,FALSE) -> 0.079531142
A25: 220.06169-7.766 | B25: 11 | C25: 10 | D25: 52 | E25: 0.86025883 | F25: 0.87527403 | G25: 0.23638221 | H25: 1002222.3 | I25: 1435895.3 | J25: 0.518748 | K25: Indole-3-acetic acid | L25: IAA | M25: o | N25: Tryptophan metabolism | O25: =VLOOKUP(A25,fecal_neg_0w!A:G,7,FALSE) -> 0.51914752
A26: 202.05128-16.408 | B26: 11 | C26: 10 | D26: 28 | E26: 0.062031042 | F26: 0.078712276 | G26: 0.02125755 | H26: 5020772.5 | I26: 7439915.3 | J26: 0.56737685 | K26: INDOLE-3-PYRUVATE | L26: IPA | M26: o | N26: Tryptophan metabolism | O26: =VLOOKUP(A26,fecal_neg_0w!A:G,7,FALSE) -> 0.4073769
A27: 202.05124-16.927 | B27: 11 | C27: 10 | D27: 94.5 | E27: 0.0060108417 | F27: 0.0099511018 | G27: 0.0026874594 | H27: 4502751.6 | I27: 3037280.5 | J27: -0.56802674 | K27: Indole-3-pyruvic acid | M27: o | O27: =VLOOKUP(A27,fecal_neg_0w!A:G,7,FALSE) -> 0.064163632
A28: 202.05126-17.793 | B28: 11 | C28: 10 | D28: 88 | E28: 0.022103705 | F28: 0.030847988 | G28: 0.0083310088 | H28: 5606882.5 | I28: 2978892.8 | J28: -0.91242264 | K28: Indole-3-pyruvic acid | M28: o | O28: =VLOOKUP(A28,fecal_neg_0w!A:G,7,FALSE) -> 0.054062077
A29: 190.05117-7.239 | B29: 11 | C29: 10 | D29: 99 | E29: 0.0021899994 | F29: 0.0041573117 | G29: 0.0011227507 | H29: 34755649 | I29: 8340728.4 | J29: -2.0590022 | K29: 5-Hydroxyindole-3-acetic acid | L29: 5-HIAA | M29: o | N29: Tryptophan metabolism | O29: =VLOOKUP(A29,fecal_neg_0w!A:G,7,FALSE) -> 0.044612472
A30: 293.11461-6.013 | B30: 11 | C30: 10 | D30: 108 | E30: 0.00021821505 | F30: 0.0019641647 | G30: 0.00053045512 | H30: 1651883.6 | I30: 86420.298 | J30: -4.256598 | K30: 6-Hydroxymelatonin | L30: 6-OHM | M30: o | N30: Tryptophan metabolism | O30: =VLOOKUP(A30,fecal_neg_0w!A:G,7,FALSE) -> 0.024062048
A31: 188.03554-5.821 | B31: 11 | C31: 10 | D31: 106 | E31: 0.00037639672 | F31: 0.002033634 | G31: 0.00054921644 | H31: 15979945 | I31: 1550061.5 | J31: -3.3658651 | K31: Kynurenic acid | L31: KYNA | M31: o | N31: Tryptophan metabolism | O31: =VLOOKUP(A31,fecal_neg_0w!A:G,7,FALSE) -> 0.026679515
A32: 108.90201-1.062 | B32: 11 | C32: 10 | D32: 110 | E32: 6.4246394e-05 | F32: 0.0019641647 | G32: 0.00053045512 | H32: 1985315.3 | I32: 138452.66 | J32: -3.8419035 | M32: x | O32: =VLOOKUP(A32,fecal_neg_0w!A:G,7,FALSE) -> 0.051471173
A33: 527.21647-14.226 | B33: 11 | C33: 10 | D33: 110 | E33: 6.4246394e-05 | F33: 0.0019641647 | G33: 0.00053045512 | H33: 474595.86 | I33: 50895.864 | J33: -3.2210792 | M33: x | O33: =VLOOKUP(A33,fecal_neg_0w!A:G,7,FALSE) -> 0.044612472
A34: 577.30243-11.824 | B34: 11 | C34: 10 | D34: 0 | E34: 6.4246394e-05 | F34: 0.0019641647 | G34: 0.00053045512 | H34: 29464.535 | I34: 389457.6 | J34: 3.7244149 | M34: x | O34: =VLOOKUP(A34,fecal_neg_0w!A:G,7,FALSE) -> 0.026679515
A35: 540.82893-0.942 | B35: 11 | C35: 10 | D35: 0 | E35: 6.4246394e-05 | F35: 0.0019641647 | G35: 0.00053045512 | H35: 14696.017 | I35: 141346.12 | J35: 3.2657353 | M35: x | O35: =VLOOKUP(A35,fecal_neg_0w!A:G,7,FALSE) -> 0.036715204
A36: 236.10553-11.87 | B36: 11 | C36: 10 | D36: 1 | E36: 6.6915326e-05 | F36: 0.0019641647 | G36: 0.00053045512 | H36: 5206652 | I36: 9499324.9 | J36: 0.867469 | M36: x | O36: =VLOOKUP(A36,fecal_neg_0w!A:G,7,FALSE) -> 0.024062048
A37: 164.92739-0.934 | B37: 11 | C37: 10 | D37: 2 | E37: 9.1356091e-05 | F37: 0.0019641647 | G37: 0.00053045512 | H37: 3606222.8 | I37: 17889321 | J37: 2.3105382 | M37: x | O37: =VLOOKUP(A37,fecal_neg_0w!A:G,7,FALSE) -> 0.024062048
A38: 136.93249-0.913 | B38: 11 | C38: 10 | D38: 2 | E38: 9.1356091e-05 | F38: 0.0019641647 | G38: 0.00053045512 | H38: 631643.87 | I38: 3252196.6 | J38: 2.3642312 | M38: x | O38: =VLOOKUP(A38,fecal_neg_0w!A:G,7,FALSE) -> 0.031237098
A39: 623.34455-13.948 | B39: 11 | C39: 10 | D39: 0 | E39: 0.00010353987 | F39: 0.0019641647 | G39: 0.00053045512 | H39: 26938.322 | I39: 232541.24 | J39: 3.1097547 | M39: x | O39: =VLOOKUP(A39,fecal_neg_0w!A:G,7,FALSE) -> 0.036715204
A40: 554.86977-0.954 | B40: 11 | C40: 10 | D40: 0 | E40: 0.00010353987 | F40: 0.0019641647 | G40: 0.00053045512 | H40: 16807.652 | I40: 254183.68 | J40: 3.9186813 | M40: x | O40: =VLOOKUP(A40,fecal_neg_0w!A:G,7,FALSE) -> 0.030212282
...

Sheet serum_neg_2w
A1: FeatureID | B1: Ctrl_n | C1: Vnam_n | D1: U_stat | E1: p-val | F1: q-val_BH | G1: q-val_BKY | H1: Ctrl_mean | I1: Vnam_mean | J1: lfc | K1: Name | L1: ReName | M1: Annotated | N1: Interested
A2: 524.27885-13.668 | B2: 9 | C2: 6 | D2: 26 | E2: 0.95464535 | F2: 0.97979211 | G2: 0.941746 | H2: 11124628 | I2: 11893877 | J2: 0.096462055 | K2: lysophosphatidylethanolamine (22:6(4Z,7Z,10Z,13Z,16Z,19Z)/0:0) | L2: LysoPE(22:6(4Z,7Z,10Z,13Z,16Z,19Z)/0:0) | M2: o | N2: Glycerophospholipid metabolism
A3: 204.06669-8.015 | B3: 9 | C3: 6 | D3: 0 | E3: 0.0003996004 | F3: 0.016014406 | G3: 0.015392554 | H3: 3225939.1 | I3: 5182588.6 | J3: 0.68395368 | K3: Indole-3-lactic acid | M3: o
A4: 204.06668-9.617 | B4: 9 | C4: 6 | D4: 42 | E4: 0.086349392 | F4: 0.34508775 | G4: 0.33168772 | H4: 28322728 | I4: 24184895 | J4: -0.22785394 | K4: Indole-3-lactic acid | L4: ILA | M4: o | N4: Interested
A5: 179.05631-1.086 | B5: 9 | C5: 6 | D5: 39 | E5: 0.18101898 | F5: 0.49851301 | G5: 0.47915535 | H5: 18281942 | I5: 13494548 | J5: -0.43804266 | K5: Acetic acid | L5: Acetate | M5: o | N5: SCFAs
A6: 191.02-1.09 | B6: 9 | C6: 6 | D6: 17 | E6: 0.27212787 | F6: 0.59270915 | G6: 0.56969378 | H6: 5015585.9 | I6: 10929249 | J6: 1.1237041 | K6: Citric acid | M6: o
A7: 191.01998-1.477 | B7: 9 | C7: 6 | D7: 20 | E7: 0.45594406 | F7: 0.73679439 | G7: 0.70818407 | H7: 32756924 | I7: 52281214 | J7: 0.67449274 | K7: Citric acid | L7: Citrate | M7: o | N7: TCA cycle
A8: 160.07693-8.378 | B8: 9 | C8: 6 | D8: 54 | E8: 0.0012576282 | F8: 0.022798266 | G8: 0.021912991 | H8: 922077 | I8: 26814.554 | J8: -5.1037991 | K8: Tryptophol | M8: o | N8: Tryptophan metabolism
A9: 241.08586-10.316 | B9: 9 | C9: 6 | D9: 37.5 | E9: 0.22354287 | F9: 0.56050616 | G9: 0.53874126 | H9: 1232915.5 | I9: 1150308.7 | J9: -0.10005286 | K9: (±)-Equol | M9: o
A10: 356.18673-15.987 | B10: 9 | C10: 6 | D10: 18 | E10: 0.27724292 | F10: 0.60012254 | G10: 0.57681931 | H10: 353370.32 | I10: 554149.07 | J10: 0.64909327 | K10: (±)-Laudanosine | M10: o
A11: 694.48034-1.033 | B11: 9 | C11: 6 | D11: 46 | E11: 0.025574426 | F11: 0.15733506 | G11: 0.15122562 | H11: 499504.66 | I11: 309584.19 | J11: -0.69016633 | K11: (15Z,19R)-25-Amino-22-hydroxy-22-oxido-17,21,23-trioxa-22λ~5~-phosphapentacos-15-en-19-yl (6Z,9Z,12Z,15Z)-6,9,12,15-octadecatetraenoate | M11: o
A12: 684.49695-1.028 | B12: 9 | C12: 6 | D12: 44 | E12: 0.04955045 | F12: 0.25061093 | G12: 0.24087951 | H12: 292669.42 | I12: 223155.09 | J12: -0.39122528 | K12: (15Z,19R)-25-Amino-22-hydroxy-22-oxido-17,21,23-trioxa-22λ~5~-phosphapentacos-15-en-19-yl (9Z,12Z)-9,12-heptadecadienoate | M12: o
A13: 239.16548-12.935 | B13: 9 | C13: 6 | D13: 6 | E13: 0.011988012 | F13: 0.10089111 | G13: 0.096973427 | H13: 143739.39 | I13: 388628.03 | J13: 1.4349345 | K13: (1S,2R,5S)-2-Isopropyl-5-methylcyclohexyl 3-oxobutanoate | M13: o
A14: 588.33129-13.774 | B14: 9 | C14: 6 | D14: 38 | E14: 0.22377622 | F14: 0.56050616 | G14: 0.53874126 | H14: 3456050.9 | I14: 2663074.2 | J14: -0.37603182 | K14: (2R)-1-{[(2-Aminoethoxy)(hydroxy)phosphoryl]oxy}-3-hydroxy-2-propanyl (7Z,10Z,13Z,16Z)-7,10,13,16-docosatetraenoate | M14: o
A15: 566.34692-14.682 | B15: 9 | C15: 6 | D15: 34 | E15: 0.45594406 | F15: 0.73679439 | G15: 0.70818407 | H15: 8402990.1 | I15: 6724708.4 | J15: -0.32143107 | K15: (2R)-3-[(9Z)-9-Heptadecenoyloxy]-2-hydroxypropyl 2-(trimethylammonio)ethyl phosphate | M15: o
A16: 743.45426-1.025 | B16: 9 | C16: 6 | D16: 40 | E16: 0.14465534 | F16: 0.44366596 | G16: 0.42643805 | H16: 132310.87 | I16: 101149.94 | J16: -0.38743612 | K16: (3R,3′S)-3-Hydroxy-4′-oxo-β,β-caroten-3′-yl hexopyranoside | M16: o
A17: 253.14476-11.382 | B17: 9 | C17: 6 | D17: 24 | E17: 0.76090673 | F17: 0.90160977 | G17: 0.86659954 | H17: 870487.02 | I17: 864950.01 | J17: -0.0092060309 | K17: (5Z)-7,10-Dihydroxy-5-tetradecen-8-ynoic acid | M17: o
A18: 363.21793-10.337 | B18: 9 | C18: 6 | D18: 9 | E18: 0.0081249737 | F18: 0.078417178 | G18: 0.075372176 | H18: 34197.05 | I18: 606035.78 | J18: 4.1474592 | K18: (5ξ,9ξ)-17-Hydroxykaur-15-en-19-oic acid | M18: o
A19: 311.223-13.77 | B19: 9 | C19: 6 | D19: 3 | E19: 0.0027972028 | F19: 0.033439288 | G19: 0.032140814 | H19: 307603.66 | I19: 1058736.5 | J19: 1.783199 | K19: (9E,11E)-13-Hydroperoxy-9,11-octadecadienoic acid | M19: o
A20: 514.28496-8.995 | B20: 9 | C20: 6 | D20: 0 | E20: 0.0003996004 | F20: 0.016014406 | G20: 0.015392554 | H20: 1100602.9 | I20: 44990605 | J20: 5.3532578 | M20: x
A21: 514.285-9.764 | B21: 9 | C21: 6 | D21: 0 | E21: 0.0003996004 | F21: 0.016014406 | G21: 0.015392554 | H21: 1884744.4 | I21: 39817525 | J21: 4.4009628 | M21: x
A22: 181.96622-1.06 | B22: 9 | C22: 6 | D22: 0 | E22: 0.0003996004 | F22: 0.016014406 | G22: 0.015392554 | H22: 10746058 | I22: 15844876 | J22: 0.5602088 | M22: x
A23: 357.83916-1.049 | B23: 9 | C23: 6 | D23: 0 | E23: 0.0003996004 | F23: 0.016014406 | G23: 0.015392554 | H23: 2960481.9 | I23: 4508516.5 | J23: 0.60682077 | M23: x
A24: 297.88352-1.048 | B24: 9 | C24: 6 | D24: 0 | E24: 0.0003996004 | F24: 0.016014406 | G24: 0.015392554 | H24: 1735724.3 | I24: 2610509.5 | J24: 0.5887936 | M24: x
A25: 257.96063-1.84 | B25: 9 | C25: 6 | D25: 0 | E25: 0.0003996004 | F25: 0.016014406 | G25: 0.015392554 | H25: 1120431.6 | I25: 1990415.5 | J25: 0.82901509 | M25: x
A26: 239.9248-1.06 | B26: 9 | C26: 6 | D26: 0 | E26: 0.0003996004 | F26: 0.016014406 | G26: 0.015392554 | H26: 1368571.3 | I26: 1893625.9 | J26: 0.46848072 | M26: x
A27: 498.29016-9.706 | B27: 9 | C27: 6 | D27: 0 | E27: 0.0003996004 | F27: 0.016014406 | G27: 0.015392554 | H27: 125653.47 | I27: 1223005.6 | J27: 3.2829085 | M27: x
A28: 219.86667-1.064 | B28: 9 | C28: 6 | D28: 0 | E28: 0.0003996004 | F28: 0.016014406 | G28: 0.015392554 | H28: 562647.71 | I28: 1062460.7 | J28: 0.91710561 | M28: x
A29: 161.99404-1 | B29: 9 | C29: 6 | D29: 0 | E29: 0.0003996004 | F29: 0.016014406 | G29: 0.015392554 | H29: 168989.28 | I29: 380558.2 | J29: 1.1711853 | M29: x
A30: 586.36516-17.207 | B30: 9 | C30: 6 | D30: 54 | E30: 0.0003996004 | F30: 0.016014406 | G30: 0.015392554 | H30: 261178.48 | I30: 72508.655 | J30: -1.8488109 | M30: x
A31: 652.8019-0.969 | B31: 9 | C31: 6 | D31: 54 | E31: 0.0003996004 | F31: 0.016014406 | G31: 0.015392554 | H31: 316872.14 | I31: 253650.18 | J31: -0.32106066 | M31: x
A32: 307.91227-0.995 | B32: 9 | C32: 6 | D32: 0 | E32: 0.0003996004 | F32: 0.016014406 | G32: 0.015392554 | H32: 73991.092 | I32: 141310.66 | J32: 0.93344676 | M32: x
A33: 421.22629-15.213 | B33: 9 | C33: 6 | D33: 16 | E33: 0.20124262 | F33: 0.54988893 | G33: 0.5285363 | H33: 6.1147053e+09 | I33: 6.3416025e+09 | J33: 0.052564476 | K33: 1,4-Bis(2-ethylhexyl) sulfosuccinate | M33: o
A34: 572.24384-9 | B34: 9 | C34: 6 | D34: 0 | E34: 0.00042623894 | F34: 0.016014406 | G34: 0.015392554 | H34: 36020.417 | I34: 2007352.4 | J34: 5.8003353 | M34: x
A35: 554.31653-10.072 | B35: 9 | C35: 6 | D35: 0 | E35: 0.00042623894 | F35: 0.016014406 | G35: 0.015392554 | H35: 32937.761 | I35: 1518197 | J35: 5.5264727 | M35: x
A36: 614.2105-9.759 | B36: 9 | C36: 6 | D36: 0 | E36: 0.00070551052 | F36: 0.018277375 | G36: 0.01756765 | H36: 28465.996 | I36: 376892.22 | J36: 3.7268406 | M36: x
A37: 387.15641-15.391 | B37: 9 | C37: 6 | D37: 18 | E37: 0.30767317 | F37: 0.63717429 | G37: 0.6124323 | H37: 4513465.4 | I37: 5017502.3 | J37: 0.15273382 | K37: 1,5-dimethyl-4-[2-(3-methyl-5-oxo-1-phenyl-4,5-dihydro-1H-pyrazol-4-yliden)hydrazino]-2-phenyl-2,3-dihydro-1H-pyrazol-3-one | M37: o
A38: 504.31039-13.791 | B38: 9 | C38: 6 | D38: 18 | E38: 0.32767233 | F38: 0.63717429 | G38: 0.6124323 | H38: 2591966.4 | I38: 2780793.6 | J38: 0.10144965 | K38: 1-[(9Z,12Z)-heptadecadienoyl]-sn-glycero-3-phosphocholine | M38: o
A39: 564.33139-13.564 | B39: 9 | C39: 6 | D39: 21 | E39: 0.52867133 | F39: 0.7713762 | G39: 0.74142304 | H39: 3972126.3 | I39: 4178128.3 | J39: 0.072945312 | K39: 1-[(9Z,12Z)-heptadecadienoyl]-sn-glycero-3-phosphocholine | M39: o
A40: 319.22806-14.455 | B40: 9 | C40: 6 | D40: 41 | E40: 0.11348651 | F40: 0.39564573 | G40: 0.38028249 | H40: 7733445.7 | I40: 5288637.6 | J40: -0.54821524 | K40: 11,12-Epoxy-(5Z,8Z,11Z)-icosatrienoic acid | M40: o
...
